<?xml version="1.0"?>
<robot name="bridge_4dof">

  <link name="base_link">
    <visual>
      <geometry>
        <sphere radius="0.05"/>
      </geometry>
    </visual>
  </link>

  <link name="first_sh">
    <visual>
      <geometry>
        <sphere radius="0.05"/>
      </geometry>
    </visual>
  </link>

  <joint name="j1" type="revolute">
    <parent link="base_link"/>
    <child link="first_sh"/>
    <origin rpy="0 0 0" xyz="0 0 0"/>
    <axis xyz="0 0 -1"/>
    <limit effort="1000.0" lower="-0.8727" upper="0.4363" velocity="0.5"/>
  </joint>

  <link name="second_sh">
    <visual>
      <geometry>
        <sphere radius="0.05"/>
      </geometry>
    </visual>
  </link>

  <joint name="j2" type="revolute">
    <parent link="first_sh"/>
    <child link="second_sh"/>
    <origin rpy="1.57075 0 0" xyz="0 0 0"/>
    <axis xyz="0 0 1"/>
    <limit effort="1000.0" lower="-0.9599" upper="0.4363" velocity="0.5"/>
  </joint>

  <link name="first_arm">
    <visual>
      <geometry>
        <cylinder length="0.4" radius="0.03"/>
      </geometry>
      <origin rpy="0 0 0" xyz="0 0 0.2"/>
    </visual>
  </link>

  <joint name="j3" type="revolute">
    <parent link="second_sh"/>
    <child link="first_arm"/>
    <origin rpy="1.57075 0 1.57075" xyz="0 0 0"/>
    <axis xyz="0 0 -1"/>
    <limit effort="1000.0" lower="-0.6981" upper="0.3491" velocity="0.5"/>
  </joint>

  <link name="second_arm">
    <visual>
      <geometry>
        <cylinder length="0.4" radius="0.03"/>
      </geometry>
      <origin rpy="1.57075 0 0" xyz="0 0.2 0"/>
    </visual>
  </link>

  <joint name="j4" type="revolute">
    <parent link="first_arm"/>
    <child link="second_arm"/>
    <origin rpy="1.57075 0 1.57075" xyz="0 0 0.4"/>
    <axis xyz="0 0 -1"/>
    <limit effort="1000.0" lower="0.1745" upper="2.0944" velocity="0.5"/>
  </joint>

  <link name="hand">
    <visual>
      <geometry>
        <sphere radius="0.05"/>
      </geometry>
      <origin rpy="0 0 0" xyz="0 0 0"/>
    </visual>
  </link>

  <joint name="j5" type="fixed">
    <parent link="second_arm"/>
    <child link="hand"/>
    <origin rpy="0 0 1.57075" xyz="0 0.4 0"/>
  </joint>

</robot>